<?xml version="1.0"?>
<robot name="clober">

  <link name="base_link">
    <visual>
      <origin xyz="0 0 0" rpy="0 0 1.570796327"/>
      <geometry>
        <mesh filename="package://clober_description/meshes/clober.dae"/>
      </geometry>
    </visual>
    <collision>
      <origin xyz="0 0 0" rpy="0 0 1.570796327"/>
      <geometry>
        <mesh filename="package://clober_description/meshes/clober_collision.stl" scale="0.001 0.001 0.001"/>
      </geometry>
    </collision>
  </link>

  <joint name="left_wheel_joint" type="continuous">
    <parent link="base_link"/>
    <child link="left_wheel_link"/>
    <origin xyz="0.0018 0.1558 0.019" rpy="0 0 0"/>
    <axis xyz="0 1 0" rpy="0 0 0"/>
  </joint>

  <link name="left_wheel_link">
    <visual>
      <origin xyz="0 0 0" rpy="0 0 -1.570796327"/>
      <geometry>
        <mesh filename="package://clober_description/meshes/wheel.dae"/>
      </geometry>
    </visual>
    <collision>
      <origin xyz="0 0 0" rpy="0 0 -1.570796327"/>
      <geometry>
        <mesh filename="package://clober_description/meshes/wheel.dae"/>
      </geometry>
    </collision>
  </link>

  <joint name="right_wheel_joint" type="continuous">
    <parent link="base_link"/>
    <child link="right_wheel_link"/>
    <origin xyz="0.0018 -0.1558 0.019" rpy="0 0 0"/>
    <axis xyz="0 1 0" rpy="0 0 0"/>
  </joint>

  <link name="right_wheel_link">
    <visual>
      <origin xyz="0 0 0" rpy="0 0 1.570796327"/>
      <geometry>
        <mesh filename="package://clober_description/meshes/wheel.dae"/>
      </geometry>
    </visual>
    <collision>
      <origin xyz="0 0 0" rpy="0 0 1.570796327"/>
      <geometry>
        <mesh filename="package://clober_description/meshes/wheel.dae"/>
      </geometry>
    </collision>
  </link>

  <joint name="imu_joint" type="fixed">
    <parent link="base_link"/>
    <child link="imu_link"/>
    <origin xyz="0.0605 0 0.0923" rpy="0 0 0"/>
  </joint>

  <link name="imu_link"/>

  <joint name="left_ultrasonic_joint" type="fixed">
    <parent link="base_link"/>
    <child link="left_ultrasonic"/>
    <origin xyz="0.18164 0.09679 0.08396" rpy="0 0 0"/>
  </joint>

  <link name="left_ultrasonic"/>

  <joint name="right_ultrasonic_joint" type="fixed">
    <parent link="base_link"/>
    <child link="right_ultrasonic"/>
    <origin xyz="0.18164 -0.09679 0.08396" rpy="0 0 0"/>
  </joint>

  <link name="right_ultrasonic"/>

  <!-- ros2 control specific -->
  <ros2_control name="clober_bot" type="system">
    <hardware>
      <plugin>ros2_control_demo_hardware/DiffBotSystemHardware</plugin>
      <param name="example_param_hw_start_duration_sec">2.0</param>
      <param name="example_param_hw_stop_duration_sec">3.0</param>
      <param name="example_param_hw_slowdown">2.0</param>
    </hardware>
    
    <joint name="left_wheel_joint">
      <command_interface name="velocity">
        <param name="min">-1</param>
        <param name="max">1</param>
      </command_interface>
      <state_interface name="position"/>
      <state_interface name="velocity"/>
    </joint>
    <joint name="right_wheel_joint">
      <command_interface name="velocity">
        <param name="min">-1</param>
        <param name="max">1</param>
      </command_interface>
      <state_interface name="position"/>
      <state_interface name="velocity"/>
    </joint>
  </ros2_control>

</robot>