<?xml version="1.0"?>
<sdf version='1.6'>
    <model name='clober'>

        <!-- <link name="base_footprint"/>

        <joint name="base_joint" type="fixed">
            <parent>base_footprint</parent>
            <child>base_link</child>
            <pose>0.0 0.0 0.020 0 0 0</pose>
        </joint> -->

        <link name="base_link">
            <visual name='visual'>
                <pose>0 0 0 0 0 1.5707963267948966</pose>
                <geometry>
                    <mesh>
                        <uri>model://clober/meshes/clober.dae</uri>
                    </mesh>
                </geometry>
            </visual>

            <collision name="base_collision">
                <pose>0 0 0.05 0 0 1.5707963267948966</pose>
                <geometry>
                    <box>
                        <size>0.41 0.41 0.1</size>
                    </box>
                </geometry>
            </collision>

            <inertial>
                <pose>0 0 0 0 0 0</pose>
                <mass>30</mass>
                <inertia>
                    <ixx>2.2124416e-03</ixx>
                    <ixy>-1.2294101e-05</ixy>
                    <ixz>3.4938785e-05</ixz>
                    <iyy>2.1193702e-03</iyy>
                    <iyz>-5.0120904e-06</iyz>
                    <izz>2.0064271e-03</izz>
                </inertia>
            </inertial>
        </link>

        <joint name="left_wheel_joint" type="revolute">
            <parent>base_link</parent>
            <child>left_wheel_link</child>
            <pose>0.0018 0.1558 0.02 -1.5707963267948966 0 0</pose>
            <axis>
                <xyz> 0 1 0 </xyz>
                <dynamics>
                    <friction> 1 </friction>
                    <damping> 1 </damping>
                    <spring_reference> 0 </spring_reference>
                    <spring_stiffness> 0 </spring_stiffness>
                </dynamics>
                <use_parent_model_frame> 1 </use_parent_model_frame>
            </axis>
        </joint>

        <joint name="right_wheel_joint" type="revolute">
            <parent>base_link</parent>
            <child>right_wheel_link</child>
            <pose>0.0018 -0.1558 0.02 -1.5707963267948966 0 0</pose>
            <axis>
                <xyz> 0 1 0 </xyz>
                <dynamics>
                    <friction> 1 </friction>
                    <damping> 1 </damping>
                    <spring_reference> 0 </spring_reference>
                    <spring_stiffness> 0 </spring_stiffness>
                </dynamics>
                <use_parent_model_frame> 1 </use_parent_model_frame>
            </axis>
        </joint>

        <link name="left_wheel_link">
            <visual name='visual'>
                <pose>0.0018 0.1558 0.02 0 0 -1.5707963267948966</pose>
                <geometry>
                    <mesh>
                        <uri>model://clober/meshes/wheel.dae</uri>
                    </mesh>
                </geometry>
            </visual>
            <collision name='left_wheel_link_collision'>
                <pose>0.0018 0.1558 0.02 0 0 -1.5707963267948966</pose>
                <geometry>
                    <mesh>
                        <uri>model://clober/meshes/wheel.dae</uri>
                    </mesh>
                </geometry>
                <surface>
                    <friction>
                        <ode>
                            <mu> 1 </mu>
                            <mu2> 1 </mu2>
                        </ode>
                    </friction>
                    <contact>
                        <ode>
                            <kp> 100000 </kp>
                            <kd> 1000 </kd>
                            <max_vel> 0.1 </max_vel>
                            <min_depth> 0.0001 </min_depth>
                        </ode>
                    </contact>
                </surface>                
            </collision>

            <inertial>
                <pose>0.0018 0.1558 0.02 0 0 -1.5707963267948966</pose>
                <mass>2.8498940e-02</mass>
                <inertia>
                    <ixx>1.1175580e-05</ixx>
                    <ixy>-4.2369783e-11</ixy>
                    <ixz>-5.9381719e-09</ixz>
                    <iyy>1.1192413e-05</iyy>
                    <iyz>-1.4400107e-11</iyz>
                    <izz>2.0712558e-05</izz>
                </inertia>
            </inertial>
        </link>

        <link name="right_wheel_link">
            <visual name='visual'>
                <pose>0.0018 -0.1558 0.02 0 0 1.5707963267948966</pose>
                <geometry>
                    <mesh>
                        <uri>model://clober/meshes/wheel.dae</uri>
                    </mesh>
                </geometry>
            </visual>
            <collision name='right_wheel_link_collision'>
                <pose>0.0018 -0.1558 0.02 0 0 1.5707963267948966</pose>
                <geometry>
                    <mesh>
                        <uri>model://clober/meshes/wheel.dae</uri>
                    </mesh>
                </geometry>
                <surface>
                    <friction>
                        <ode>
                            <mu> 1 </mu>
                            <mu2> 1 </mu2>
                        </ode>
                    </friction>
                    <contact>
                        <ode>
                            <kp> 100000 </kp>
                            <kd> 1000 </kd>
                            <max_vel> 0.1 </max_vel>
                            <min_depth> 0.0001 </min_depth>
                        </ode>
                    </contact>
                </surface>                
            </collision>
            <inertial>
                <pose>0.0018 -0.1558 0.02 0 0 1.5707963267948966</pose>
                <mass>2.8498940e-02</mass>
                <inertia>
                    <ixx>1.1175580e-05</ixx>
                    <ixy>-4.2369783e-11</ixy>
                    <ixz>-5.9381719e-09</ixz>
                    <iyy>1.1192413e-05</iyy>
                    <iyz>-1.4400107e-11</iyz>
                    <izz>2.0712558e-05</izz>
                </inertia>
            </inertial>
        </link>

        <joint name="lidar_joint" type="fixed">
            <parent>base_link</parent>
            <child>laser_link</child>
            <pose>0.159 0 0.1565 3.1415926535897931 0 0</pose>
        </joint>

        <link name="laser_link">
            <visual name="lidar_sensor_visual">
                <pose>0.159 0 0.1565 3.1415926535897931 0 0</pose>
                <geometry>
                    <mesh>
                        <uri>model://clober/meshes/include/tim571.stl</uri>
                    </mesh>
                </geometry>
            </visual>
            <sensor name="tim_571" type="ray">
                <always_on>true</always_on>
                <visualize>true</visualize>
                <pose>0.159 0 0.1565 0 0 0</pose>
                <update_rate>20</update_rate>
                <ray>
                    <scan>
                        <horizontal>
                            <samples>720</samples>
                            <resolution>0.25</resolution>
                            <min_angle>-1.5707963267948966</min_angle>
                            <max_angle>1.5707963267948966</max_angle>
                        </horizontal>
                    </scan>
                    <range>
                        <min>0.05</min>
                        <max>25.0</max>
                        <resolution>0.015000</resolution>
                    </range>
                    <noise>
                        <type>gaussian</type>
                        <mean>0.0</mean>
                        <stddev>0.01</stddev>
                    </noise>
                </ray>
                <plugin name="clober_lidar" filename="libgazebo_ros_ray_sensor.so">
                    <ros>
                        <remapping>~/out:=scan</remapping>
                    </ros>
                    <output_type>sensor_msgs/LaserScan</output_type>
                    <frame_name>laser_link</frame_name>
                </plugin>
            </sensor>
        </link>

        <joint name="caster_joint1" type="revolute">
            <parent>base_link</parent>
            <child>caster_link1</child>
            <pose>0.11 0.13 -0.04 1.5707963267948966 0 0</pose>
            <axis>
                <xyz> 0 1 0 </xyz>
                <dynamics>
                    <friction> 0.1 </friction>
                    <damping> 0.1 </damping>
                    <spring_reference> 0 </spring_reference>
                    <spring_stiffness> 0 </spring_stiffness>
                </dynamics>
                <use_parent_model_frame> 1 </use_parent_model_frame>
            </axis>
        </joint>

        <link name="caster_link1">
            <collision name="caster_link1_collision">
                <pose>0.11 0.13 -0.04 1.5707963267948966 0 0</pose>
                <geometry>
                    <cylinder>
                        <radius>0.025</radius>
                        <length>0.02</length>
                    </cylinder>
                </geometry>
                <surface>
                    <friction>
                        <ode>
                            <mu> 1 </mu>
                            <mu2> 1 </mu2>
                        </ode>
                    </friction>
                    <contact>
                        <ode>
                            <kp> 100000 </kp>
                            <kd> 1000 </kd>
                            <max_vel> 0.1 </max_vel>
                            <min_depth> 0.0001 </min_depth>
                        </ode>
                    </contact>
                </surface>
            </collision>
            <inertial>
                <pose>0.11 0.13 -0.04 1.5707963267948966 0 0</pose>
                <mass>0.005</mass>
                <inertia>
                    <ixx>0.001</ixx>
                    <ixy>0.0</ixy>
                    <ixz>0.0</ixz>
                    <iyy>0.001</iyy>
                    <iyz>0.0</iyz>
                    <izz>0.001</izz>
                </inertia>
            </inertial>
        </link>

        <joint name="caster_joint2" type="revolute">
            <parent>base_link</parent>
            <child>caster_link2</child>
            <pose>-0.15 0.13 -0.04 1.5707963267948966 0 0</pose>
            <axis>
                <xyz> 0 1 0 </xyz>
                <dynamics>
                    <friction> 0.1 </friction>
                    <damping> 0.1 </damping>
                    <spring_reference> 0 </spring_reference>
                    <spring_stiffness> 0 </spring_stiffness>
                </dynamics>
                <use_parent_model_frame> 1 </use_parent_model_frame>
            </axis>
        </joint>

        <link name="caster_link2">
            <collision name="caster_link2_collision">
                <pose>-0.15 0.13 -0.04 1.5707963267948966 0 0</pose>
                <geometry>
                    <cylinder>
                        <radius>0.025</radius>
                        <length>0.02</length>
                    </cylinder>
                </geometry>
                <surface>
                    <friction>
                        <ode>
                            <mu> 1 </mu>
                            <mu2> 1 </mu2>
                        </ode>
                    </friction>
                    <contact>
                        <ode>
                            <kp> 100000 </kp>
                            <kd> 1000 </kd>
                            <max_vel> 0.1 </max_vel>
                            <min_depth> 0.0001 </min_depth>
                        </ode>
                    </contact>
                </surface>                
            </collision>

            <inertial>
                <pose>-0.15 0.13 -0.04 1.5707963267948966 0 0</pose>
                <mass>0.005</mass>
                <inertia>
                    <ixx>0.001</ixx>
                    <ixy>0.0</ixy>
                    <ixz>0.0</ixz>
                    <iyy>0.001</iyy>
                    <iyz>0.0</iyz>
                    <izz>0.001</izz>
                </inertia>
            </inertial>
        </link>

        <joint name="caster_joint3" type="revolute">
            <parent>base_link</parent>
            <child>caster_link3</child>
            <pose>0.11 -0.13 -0.04 1.5707963267948966 0 0</pose>
            <axis>
                <xyz> 0 1 0 </xyz>
                <dynamics>
                    <friction> 0.1 </friction>
                    <damping> 0.1 </damping>
                    <spring_reference> 0 </spring_reference>
                    <spring_stiffness> 0 </spring_stiffness>
                </dynamics>
                <use_parent_model_frame> 1 </use_parent_model_frame>
            </axis>
        </joint>

        <link name="caster_link3">
            <collision name="caster_link3_collision">
                <pose>0.11 -0.13 -0.04 1.5707963267948966 0 0</pose>
                <geometry>
                    <cylinder>
                        <radius>0.025</radius>
                        <length>0.02</length>
                    </cylinder>
                </geometry>
                <surface>
                    <friction>
                        <ode>
                            <mu> 1 </mu>
                            <mu2> 1 </mu2>
                        </ode>
                    </friction>
                    <contact>
                        <ode>
                            <kp> 100000 </kp>
                            <kd> 1000 </kd>
                            <max_vel> 0.1 </max_vel>
                            <min_depth> 0.0001 </min_depth>
                        </ode>
                    </contact>
                </surface>                
            </collision>

            <inertial>
                <pose>0.11 -0.13 -0.04 1.5707963267948966 0 0</pose>
                <mass>0.005</mass>
                <inertia>
                    <ixx>0.001</ixx>
                    <ixy>0.0</ixy>
                    <ixz>0.0</ixz>
                    <iyy>0.001</iyy>
                    <iyz>0.0</iyz>
                    <izz>0.001</izz>
                </inertia>

            </inertial>
        </link>

        <joint name="caster_joint4" type="revolute">

            <parent>base_link</parent>
            <child>caster_link4</child>
            <pose>-0.15 -0.13 -0.04 1.5707963267948966 0 0</pose>
            <axis>
                <xyz> 0 1 0 </xyz>
                <dynamics>
                    <friction> 0.1 </friction>
                    <damping> 0.1 </damping>
                    <spring_reference> 0 </spring_reference>
                    <spring_stiffness> 0 </spring_stiffness>
                </dynamics>
                <use_parent_model_frame> 1 </use_parent_model_frame>
            </axis>
        </joint>

        <link name="caster_link4">
            <collision name="caster_link4_collision">
                <pose>-0.15 -0.13 -0.04 1.5707963267948966 0 0</pose>
                <geometry>
                    <cylinder>
                        <radius>0.025</radius>
                        <length>0.02</length>
                    </cylinder>
                </geometry>
                <surface>
                    <friction>
                        <ode>
                            <mu> 1 </mu>
                            <mu2> 1 </mu2>
                        </ode>
                    </friction>
                    <contact>
                        <ode>
                            <kp> 100000 </kp>
                            <kd> 1000 </kd>
                            <max_vel> 0.1 </max_vel>
                            <min_depth> 0.0001 </min_depth>
                        </ode>
                    </contact>
                </surface>                
            </collision>

            <inertial>
                <pose>-0.15 -0.13 -0.04 1.5707963267948966 0 0</pose>
                <mass>0.005</mass>
                <inertia>
                    <ixx>0.001</ixx>
                    <ixy>0.0</ixy>
                    <ixz>0.0</ixz>
                    <iyy>0.001</iyy>
                    <iyz>0.0</iyz>
                    <izz>0.001</izz>
                </inertia>

            </inertial>
        </link>

        <plugin name="clober_diff_drive" filename="libgazebo_ros_diff_drive.so">
            <update_rate>30</update_rate>

            <left_joint>left_wheel_joint</left_joint>
            <right_joint>right_wheel_joint</right_joint>

            <wheel_separation>0.310</wheel_separation>
            <wheel_diameter>0.17</wheel_diameter>

            <max_wheel_torque>20</max_wheel_torque>
            <max_wheel_acceleration>1.0</max_wheel_acceleration>

            <command_topic>cmd_vel</command_topic>

            <publish_odom>true</publish_odom>
            <publish_odom_tf>true</publish_odom_tf>
            <publish_wheel_tf>false</publish_wheel_tf>

            <odometry_topic>odom</odometry_topic>
            <odometry_frame>odom</odometry_frame>
            <robot_base_frame>base_link</robot_base_frame>
        </plugin>

        <plugin
            name="clober_joint_state"
            filename="libgazebo_ros_joint_state_publisher.so">
            <ros>
                <remapping>~/out:=joint_states</remapping>
            </ros>
            <update_rate>30</update_rate>
            <joint_name>left_wheel_joint</joint_name>
            <joint_name>right_wheel_joint</joint_name>
        </plugin>

        <gazebo reference="base_link">
            <material>Gazebo/White</material>
        </gazebo>

        <gazebo reference="left_wheel_link">
            <mu1>0.1</mu1>
            <mu2>0.1</mu2>
            <kp>500000.0</kp>
            <kd>10.0</kd>
            <minDepth>0.001</minDepth>
            <maxVel>0.1</maxVel>
            <fdir1>1 0 0</fdir1>
            <material>Gazebo/FlatBlack</material>
        </gazebo>

        <gazebo reference="right_wheel_link">
            <mu1>0.1</mu1>
            <mu2>0.1</mu2>
            <kp>500000.0</kp>
            <kd>10.0</kd>
            <minDepth>0.001</minDepth>
            <maxVel>0.1</maxVel>
            <fdir1>1 0 0</fdir1>
            <material>Gazebo/FlatBlack</material>
        </gazebo>

        <gazebo reference="caster_link1">
            <mu1>0.05</mu1>
            <mu2>0.05</mu2>
            <kp>100000.0</kp>
            <kd>100.0</kd>
            <minDepth>0.001</minDepth>
            <maxVel>1.0</maxVel>
            <fdir1>1 0 0</fdir1>
            <material>Gazebo/FlatBlack</material>
        </gazebo>

        <gazebo reference="caster_link2">
            <mu1>0.05</mu1>
            <mu2>0.05</mu2>
            <kp>100000.0</kp>
            <kd>100.0</kd>
            <minDepth>0.001</minDepth>
            <maxVel>1.0</maxVel>
            <fdir1>1 0 0</fdir1>
            <material>Gazebo/FlatBlack</material>
        </gazebo>

        <gazebo reference="caster_link3">
            <mu1>0.05</mu1>
            <mu2>0.05</mu2>
            <kp>100000.0</kp>
            <kd>100.0</kd>
            <minDepth>0.001</minDepth>
            <maxVel>1.0</maxVel>
            <fdir1>1 0 0</fdir1>
            <material>Gazebo/FlatBlack</material>
        </gazebo>

        <gazebo reference="caster_link4">
            <mu1>0.05</mu1>
            <mu2>0.05</mu2>
            <kp>100000.0</kp>
            <kd>100.0</kd>
            <minDepth>0.001</minDepth>
            <maxVel>1.0</maxVel>
            <fdir1>1 0 0</fdir1>
            <material>Gazebo/FlatBlack</material>
        </gazebo>

    </model>
</sdf>